GTCEuStartupEvents.registry('gtceu:recipe_type', event => {
   event.create('mechanical_conjuration_institute')
   .category('topofthemorningyallmynameisjacksepticeye')
   .setEUIO('in')
   .setMaxIOSize(3, 1, 2, 1)
   .setSlotOverlay(true, true, GuiTextures.SOLIDIFIER_OVERLAY)
   .setProgressBar(GuiTextures.PROGRESS_BAR_GAS_COLLECTOR, FillDirection.LEFT_TO_RIGHT)
   .setSound(GTSoundEntries.BATH)
})

GTCEuStartupEvents.registry('gtceu:machine', event => {

   event.create('mechanical_conjuration_institute', 'multiblock')
   .rotationState(RotationState.NON_Y_AXIS)
        .machine((holder) => new $CoilWorkableElectricMultiblockMachine(holder))
        .recipeModifiers([GTRecipeModifiers.PARALLEL_HATCH, (machine, recipe) => GTRecipeModifiers.pyrolyseOvenOverclock(machine, recipe)])
        .recipeTypes([GTRecipeTypes.get('mechanical_conjuration_institute')])
        .appearanceBlock(() => Block.getBlock("gtceu:heatproof_machine_casing"))
        .pattern(definition => FactoryBlockPattern.start()
.aisle("AABBBBBBBAA", "AAAAABAAAAA", "AAAAABAAAAA", "AAAAABAAAAA", "AAAAABAAAAA", "AAAAABAAAAA", "AAAAAAAAAAA", "AAAAAAAAAAA", "AAAAAAAAAAA", "AAAAAAAAAAA", "AAAAAAAAAAA", "AAAAAAAAAAA", "AAAAAAAAAAA")
.aisle("ABBCBBBCBBA", "AAADAAADAAA", "AAADAAADAAA", "AAADAAADAAA", "AAADAAADAAA", "AAADDBDDAAA", "AAAAABAAAAA", "AAAAABAAAAA", "AAAAAAAAAAA", "AAAAAAAAAAA", "AAAAAAAAAAA", "AAAAAAAAAAA", "AAAAAAAAAAA")
.aisle("BBCCBBBCCBB", "AAEECCCEEAA", "AAECFFFCEAA", "AAECFFFCEAA", "AAECFFFCEAA", "AAEECCCEEAA", "AAAECCCEAAA", "AAABBBBBAAA", "AAAAABAAAAA", "AAAAABAAAAA", "AAAAABAAAAA", "AAAAABAAAAA", "AAAAAAAAAAA")
.aisle("BCCCCCCCCCB", "ADEAAAAAEDA", "ADCFAAAFCDA", "ADCFAAAFCDA", "ADCFAAAFCDA", "ADEAAAAAEDA", "AAECCCCCEAA", "AABBBBBBBAA", "AAABFFFBAAA", "AAABFFFBAAA", "AAABFFFBAAA", "AAABBBBBAAA", "AAAAAAAAAAA")
.aisle("BBBCCCCCBBB", "AACAAAAACAA", "AAFAAAAAFAA", "AAFAAAAAFAA", "AAFAAAAAFAA", "ADCAAAAACDA", "AACCCCCCCAA", "AABBBBBBBAA", "AAAFAAAFAAA", "AAAFAAAFAAA", "AAAFAAAFAAA", "AAABBABBAAA", "AAAABBBAAAA")
.aisle("BBBCCCCCBBB", "BACAAGAACAB", "BAFAAGAAFAB", "BAFAAGAAFAB", "BAFAAGAAFAB", "BBCAAGAACBB", "ABCCCGCCCBA", "ABBBBGBBBBA", "AABFAGAFBAA", "AABFAGAFBAA", "AABFAGAFBAA", "AABBAGBBBAA", "AAAABBBAAAA")
.aisle("BBBCCCCCBBB", "AACAAAAACAA", "AAFAAAAAFAA", "AAFAAAAAFAA", "AAFAAAAAFAA", "ADCAAAAACDA", "AACCCCCCCAA", "AABBBBBBBAA", "AAAFAAAFAAA", "AAAFAAAFAAA", "AAAFAAAFAAA", "AAABBABBAAA", "AAAABBBAAAA")
.aisle("BCCCCCCCCCB", "ADEAAAAAEDA", "ADCFAAAFCDA", "ADCFAAAFCDA", "ADCFAAAFCDA", "ADEAAAAAEDA", "AAECCCCCEAA", "AABBBBBBBAA", "AAABFFFBAAA", "AAABFFFBAAA", "AAABFFFBAAA", "AAABBBBBAAA", "AAAAAAAAAAA")
.aisle("BBCCBBBCCBB", "AAEECCCEEAA", "AAECFFFCEAA", "AAECFFFCEAA", "AAECFFFCEAA", "AAEECCCEEAA", "AAAECCCEAAA", "AAABBBBBAAA", "AAAAABAAAAA", "AAAAABAAAAA", "AAAAABAAAAA", "AAAAABAAAAA", "AAAAAAAAAAA")
.aisle("ABBCBBBCBBA", "AAADAAADAAA", "AAADAAADAAA", "AAADAAADAAA", "AAADAAADAAA", "AAADDBDDAAA", "AAAAABAAAAA", "AAAAABAAAAA", "AAAAAAAAAAA", "AAAAAAAAAAA", "AAAAAAAAAAA", "AAAAAAAAAAA", "AAAAAAAAAAA")
.aisle("AABBBBBBBAA", "AAABBLBBAAA", "AAAABBBAAAA", "AAAABBBAAAA", "AAAAABAAAAA", "AAAAABAAAAA", "AAAAAAAAAAA", "AAAAAAAAAAA", "AAAAAAAAAAA", "AAAAAAAAAAA", "AAAAAAAAAAA", "AAAAAAAAAAA", "AAAAAAAAAAA")
   .where("A", Predicates.any())
   .where("B", Predicates.blocks("gtceu:heatproof_machine_casing")
      .or(Predicates.autoAbilities(definition.getRecipeTypes()))
      .or(Predicates.abilities(PartAbility.MAINTENANCE).setExactLimit(1))
      .or(Predicates.abilities(PartAbility.PARALLEL_HATCH).setMaxGlobalLimited(1)))
   .where("C", Predicates.blocks("gtceu:nexus_steel_casing"))
   .where("D", Predicates.blocks("gtceu:echolumium_frame"))
   .where("E", Predicates.blocks("gtceu:metallurgically_enhanced_source_casing"))
   .where('F', Predicates.heatingCoils())
   .where("G", Predicates.blocks("gtceu:steel_pipe_casing"))
   .where('L', Predicates.controller(Predicates.blocks(definition.get())))
   .build())
   .workableCasingModel('gtceu:block/casings/solid/machine_casing_heatproof', 'gtceu:block/machines/alloy_smelter')

})