GTCEuStartupEvents.registry('gtceu:recipe_type', event => {

    event.create('metaphysical_metallurgy_tainter')
    .category('doyouseebananamanhoppingoveronthewhitehotsand')
    .setEUIO('in')
    .setMaxIOSize(1, 1, 2, 1)
    .setSlotOverlay(false, false, GuiTextures.SLOT)
    .setProgressBar(GuiTextures.PROGRESS_BAR_CRYSTALLIZATION, FillDirection.LEFT_TO_RIGHT)
    .setSound(GTSoundEntries.BATH)
})

GTCEuStartupEvents.registry('gtceu:machine', event => {
    event.create('metaphysical_metallurgy_tainter', "multiblock")
    .rotationState(RotationState.NON_Y_AXIS)
        .recipeModifiers([GTRecipeModifiers.OC_NON_PERFECT_SUBTICK])
        .recipeTypes([GTRecipeTypes.get('metaphysical_metallurgy_tainter')])
        .appearanceBlock(() => Block.getBlock("gtceu:magikstone_casing"))
        .pattern(definition => FactoryBlockPattern.start()
.aisle("AAAAAAAAAAAAAAAAAAA", "AAAAAAAAAAAAAAAAAAA", "AAAAAAAAAAAAAAAAAAA", "AAAAAAAAAAAAAAAAAAA", "AAAAAAAAAAAAAAAAAAA", "AAAAAAAAAAAAAAAAAAA", "AAAAAAAAABAAAAAAAAA", "AAAAAAAAABAAAAAAAAA", "AAAAAAAAABAAAAAAAAA", "AAAAAABBBBBBBAAAAAA", "AAAAAAAAABAAAAAAAAA", "AAAAAAAAABAAAAAAAAA", "AAAAAAAAABAAAAAAAAA", "AAAAAAAAAAAAAAAAAAA", "AAAAAAAAAAAAAAAAAAA", "AAAAAAAAAAAAAAAAAAA", "AAAAAAAAAAAAAAAAAAA", "AAAAAAAAAAAAAAAAAAA", "AAAAAAAAAAAAAAAAAAA")
.aisle("AAAAAAAAAAAAAAAAAAA", "AAAAAAAAAAAAAAAAAAA", "AAAAAAAAAAAAAAAAAAA", "AAAAAAAAAAAAAAAAAAA", "AAAAAAAAABAAAAAAAAA", "AAAAAAAAABAAAAAAAAA", "AAAAAAAAACAAAAAAAAA", "AAAAAAAAACAAAAAAAAA", "AAAAAAAAACAAAAAAAAA", "AAAABBCCCCCCCBBAAAA", "AAAAAAAAACAAAAAAAAA", "AAAAAAAAACAAAAAAAAA", "AAAAAAAAACAAAAAAAAA", "AAAAAAAAABAAAAAAAAA", "AAAAAAAAABAAAAAAAAA", "AAAAAAAAAAAAAAAAAAA", "AAAAAAAAAAAAAAAAAAA", "AAAAAAAAAAAAAAAAAAA", "AAAAAAAAAAAAAAAAAAA")
.aisle("AAAAAAAAAAAAAAAAAAA", "AAAAAAAAAAAAAAAAAAA", "AAAAAAAAAAAAAAAAAAA", "AAAAAAAAABAAAAAAAAA", "AAAAAAAAACAAAAAAAAA", "AAAAAAAAACAAAAAAAAA", "AAAAAABBBCBBBAAAAAA", "AAAAAABAAAAABAAAAAA", "AAAAAABAAAAABAAAAAA", "AAABCCCAADAACCCBAAA", "AAAAAABAAAAABAAAAAA", "AAAAAABAAAAABAAAAAA", "AAAAAABBBCBBBAAAAAA", "AAAAAAAAACAAAAAAAAA", "AAAAAAAAACAAAAAAAAA", "AAAAAAAAABAAAAAAAAA", "AAAAAAAAAAAAAAAAAAA", "AAAAAAAAAAAAAAAAAAA", "AAAAAAAAAAAAAAAAAAA")
.aisle("AAAAAAAAAAAAAAAAAAA", "AAAAAAAAAAAAAAAAAAA", "AAAAAAAAABAAAAAAAAA", "AAAAAAABBCBBAAAAAAA", "AAAAAABBACABBAAAAAA", "AAAAABBAAAAABBAAAAA", "AAAABBBAAAAABBBAAAA", "AAABBAAAAAAAAABBAAA", "AAABAAAAAAAAAAABAAA", "AABCCAAAADAAAACCBAA", "AAABAAAAAAAAAAABAAA", "AAABBAAAAAAAAABBAAA", "AAAABBBAAAAABBBAAAA", "AAAAABBAAAAABBAAAAA", "AAAAAABBACABBAAAAAA", "AAAAAAABBCBBAAAAAAA", "AAAAAAAAABAAAAAAAAA", "AAAAAAAAAAAAAAAAAAA", "AAAAAAAAAAAAAAAAAAA")
.aisle("AAAAAAAAAAAAAAAAAAA", "AAAAAAAAABAAAAAAAAA", "AAAAAAAAACAAAAAAAAA", "AAAAAABBACABBAAAAAA", "AAAAAAAAAAAAAAAAAAA", "AAAAAAAAAAAAAAAAAAA", "AAABAAAAADAAAAABAAA", "AAABAAAAADAAAAABAAA", "AAAAAAAAADAAAAAAAAA", "ABCCAADDDDDDDAACCBA", "AAAAAAAAADAAAAAAAAA", "AAABAAAAADAAAAABAAA", "AAABAAAAADAAAAABAAA", "AAAAAAAAAAAAAAAAAAA", "AAAAAAAAAAAAAAAAAAA", "AAAAAABBACABBAAAAAA", "AAAAAAAAACAAAAAAAAA", "AAAAAAAAABAAAAAAAAA", "AAAAAAAAAAAAAAAAAAA")
.aisle("AAAAAAAAAAAAAAAAAAA", "AAAAAAAAABAAAAAAAAA", "AAAAAAAAACAAAAAAAAA", "AAAAABBAAAAABBAAAAA", "AAAAAAAAAAAAAAAAAAA", "AAABAAAAADAAAAABAAA", "AAABAAAAADAAAAABAAA", "AAAAAAAAAAAAAAAAAAA", "AAAAAAAAAAAAAAAAAAA", "ABCAADDAAAAADDAACBA", "AAAAAAAAAAAAAAAAAAA", "AAAAAAAAAAAAAAAAAAA", "AAABAAAAADAAAAABAAA", "AAABAAAAADAAAAABAAA", "AAAAAAAAAAAAAAAAAAA", "AAAAABBAAAAABBAAAAA", "AAAAAAAAACAAAAAAAAA", "AAAAAAAAABAAAAAAAAA", "AAAAAAAAAAAAAAAAAAA")
.aisle("AAAAAAAAABAAAAAAAAA", "AAAAAAAAACAAAAAAAAA", "AAAAAABBBCBBBAAAAAA", "AAAABBAAAAAAABBAAAA", "AAABAAAAAAAAAAABAAA", "AAABAAAAADAAAAABAAA", "AABBAAAAAAAAAAABBAA", "AABAAAAAAAAAAAAABAA", "AABAAAAAAAAAAAAABAA", "BCCADDAAAAAAADDACCB", "AABAAAAAAAAAAAAABAA", "AABAAAAAAAAAAAAABAA", "AABBAAAAAAAAAAABBAA", "AAABAAAAADAAAAABAAA", "AAABAAAAADAAAAABAAA", "AAAABBBAAAAABBBAAAA", "AAAAAABBBCBBBAAAAAA", "AAAAAAAAACAAAAAAAAA", "AAAAAAAAABAAAAAAAAA")
.aisle("AAAAAAAAABAAAAAAAAA", "AAAAAAAAACAAAAAAAAA", "AAAAAABAAAAABAAAAAA", "AAABBAAAAAAAAABBAAA", "AAABAAAAADAAAAABAAA", "AAAAAAAAADAAAAAAAAA", "AABAAAAAAAAAAAAABAA", "AAAAAAAAAAAAAAAAAAA", "AAAAAAAAAAAAAAAAAAA", "BCAADAAAAAAAAADAACB", "AAAAAAAAAAAAAAAAAAA", "AAAAAAAAAAAAAAAAAAA", "AABAAAAAAAAAAAAABAA", "AAAAAAAAAAAAAAAAAAA", "AAABAAAAADAAAAABAAA", "AAABBAAAAAAAAABBAAA", "AAAAAABAAAAABAAAAAA", "AAAAAAAAACAAAAAAAAA", "AAAAAAAAABAAAAAAAAA")
.aisle("AAAAAAAAABAAAAAAAAA", "AAAAAAAAACAAAAAAAAA", "AAAAAABAAAAABAAAAAA", "AAABAAAAAAAAAAABAAA", "AAAAAAAAADAAAAAAAAA", "AAAAAAAAAAAAAAAAAAA", "AABAAAAAAAAAAAAABAA", "AAAAAAAAAAAAAAAAAAA", "AAAAAAAAAAAAAAAAAAA", "BCAADAAAAAAAAADAACB", "AAAAAAAAAAAAAAAAAAA", "AAAAAAAAAAAAAAAAAAA", "AABAAAAAAAAAAAAABAA", "AAAAAAAAAAAAAAAAAAA", "AAAAAAAAADAAAAAAAAA", "AAABAAAAAAAAAAABAAA", "AAAAAABAAAAABAAAAAA", "AAAAAAAAACAAAAAAAAA", "AAAAAAAAABAAAAAAAAA")
.aisle("AAAAAABBBBBBBAAAAAA", "AAAABBCCCCCCCBBAAAA", "AAABCCCAADAACCCBAAA", "AABCCAAAADAAAACCBAA", "ABCCAAADDDDDAAACCBA", "ABCAADDDAAADDDAACBA", "BCCADDAAAAAAADDACCB", "BCAADAAAAAAAAADAACB", "BCAADAAAAAAAAADAACB", "BCDDDAAAAAAAAADDDCB", "BCAADAAAAAAAAADAACB", "BCAADAAAAAAAAADAACB", "BCCADDAAAAAAADDACCB", "ABCAADDAAAAADDAACBA", "ABCCAADDDDDDDAACCBA", "AABCCAAAADAAAACCBAA", "AAABCCCAADAACCCBAAA", "AAAABBCCCCCCCBBAAAA", "AAAAAABBBBBBBAAAAAA")
.aisle("AAAAAAAAABAAAAAAAAA", "AAAAAAAAACAAAAAAAAA", "AAAAAABAAAAABAAAAAA", "AAABAAAAAAAAAAABAAA", "AAAAAAAAADAAAAAAAAA", "AAAAAAAAAAAAAAAAAAA", "AABAAAAAAAAAAAAABAA", "AAAAAAAAAAAAAAAAAAA", "AAAAAAAAAAAAAAAAAAA", "BCAADAAAAAAAAADAACB", "AAAAAAAAAAAAAAAAAAA", "AAAAAAAAAAAAAAAAAAA", "AABAAAAAAAAAAAAABAA", "AAAAAAAAAAAAAAAAAAA", "AAAAAAAAADAAAAAAAAA", "AAABAAAAAAAAAAABAAA", "AAAAAABAAAAABAAAAAA", "AAAAAAAAACAAAAAAAAA", "AAAAAAAAABAAAAAAAAA")
.aisle("AAAAAAAAABAAAAAAAAA", "AAAAAAAAACAAAAAAAAA", "AAAAAABAAAAABAAAAAA", "AAABBAAAAAAAAABBAAA", "AAABAAAAADAAAAABAAA", "AAAAAAAAADAAAAAAAAA", "AABAAAAAAAAAAAAABAA", "AAAAAAAAAAAAAAAAAAA", "AAAAAAAAAAAAAAAAAAA", "BCAADAAAAAAAAADAACB", "AAAAAAAAAAAAAAAAAAA", "AAAAAAAAAAAAAAAAAAA", "AABAAAAAAAAAAAAABAA", "AAAAAAAAAAAAAAAAAAA", "AAABAAAAADAAAAABAAA", "AAABBAAAAAAAAABBAAA", "AAAAAABAAAAABAAAAAA", "AAAAAAAAACAAAAAAAAA", "AAAAAAAAABAAAAAAAAA")
.aisle("AAAAAAAAABAAAAAAAAA", "AAAAAAAAACAAAAAAAAA", "AAAAAABBBCBBBAAAAAA", "AAAABBAAAAAAABBAAAA", "AAABAAAAAAAAAAABAAA", "AAABAAAAADAAAAABAAA", "AABBAAAAAAAAAAABBAA", "AABAAAAAAAAAAAAABAA", "AABAAAAAAAAAAAAABAA", "BCCADDAAAAAAADDACCB", "AABAAAAAAAAAAAAABAA", "AABAAAAAAAAAAAAABAA", "AABBAAAAAAAAAAABBAA", "AAABAAAAADAAAAABAAA", "AAABAAAAADAAAAABAAA", "AAAABBBAAAAABBBAAAA", "AAAAAABBBCBBBAAAAAA", "AAAAAAAAACAAAAAAAAA", "AAAAAAAAABAAAAAAAAA")
.aisle("AAAAAAAAAAAAAAAAAAA", "AAAAAAAAABAAAAAAAAA", "AAAAAAAAACAAAAAAAAA", "AAAAABBAAAAABBAAAAA", "AAAAAAAAAAAAAAAAAAA", "AAABAAAAADAAAAABAAA", "AAABAAAAADAAAAABAAA", "AAAAAAAAAAAAAAAAAAA", "AAAAAAAAAAAAAAAAAAA", "ABCAADDAAAAADDAACBA", "AAAAAAAAAAAAAAAAAAA", "AAAAAAAAAAAAAAAAAAA", "AAABAAAAADAAAAABAAA", "AAABAAAAADAAAAABAAA", "AAAAAAAAAAAAAAAAAAA", "AAAAABBAAAAABBAAAAA", "AAAAAAAAACAAAAAAAAA", "AAAAAAAAABAAAAAAAAA", "AAAAAAAAAAAAAAAAAAA")
.aisle("AAAAAAAAAAAAAAAAAAA", "AAAAAAAAABAAAAAAAAA", "AAAAAAAAACAAAAAAAAA", "AAAAAABBACABBAAAAAA", "AAAAAAAAAAAAAAAAAAA", "AAAAAAAAAAAAAAAAAAA", "AAABAAAAADAAAAABAAA", "AAABAAAAADAAAAABAAA", "AAAAAAAAADAAAAAAAAA", "ABCCAADDDDDDDAACCBA", "AAAAAAAAADAAAAAAAAA", "AAABAAAAADAAAAABAAA", "AAABAAAAADAAAAABAAA", "AAAAAAAAAAAAAAAAAAA", "AAAAAAAAAAAAAAAAAAA", "AAAAAABBACABBAAAAAA", "AAAAAAAAACAAAAAAAAA", "AAAAAAAAABAAAAAAAAA", "AAAAAAAAAAAAAAAAAAA")
.aisle("AAAAAAAAAAAAAAAAAAA", "AAAAAAAAAAAAAAAAAAA", "AAAAAAAAABAAAAAAAAA", "AAAAAAABBCBBAAAAAAA", "AAAAAABBACABBAAAAAA", "AAAAABBAAAAABBAAAAA", "AAAABBBAAAAABBBAAAA", "AAABBAAAAAAAAABBAAA", "AAABAAAAAAAAAAABAAA", "AABCCAAAADAAAACCBAA", "AAABAAAAAAAAAAABAAA", "AAABBAAAAAAAAABBAAA", "AAAABBBAAAAABBBAAAA", "AAAAABBAAAAABBAAAAA", "AAAAAABBACABBAAAAAA", "AAAAAAABBCBBAAAAAAA", "AAAAAAAAABAAAAAAAAA", "AAAAAAAAAAAAAAAAAAA", "AAAAAAAAAAAAAAAAAAA")
.aisle("AAAAAAAAAAAAAAAAAAA", "AAAAAAAAAAAAAAAAAAA", "AAAAAAAAAAAAAAAAAAA", "AAAAAAAAABAAAAAAAAA", "AAAAAAAAACAAAAAAAAA", "AAAAAAAAACAAAAAAAAA", "AAAAAABBBCBBBAAAAAA", "AAAAAABAAAAABAAAAAA", "AAAAAABAAAAABAAAAAA", "AAABCCCAADAACCCBAAA", "AAAAAABAAAAABAAAAAA", "AAAAAABAAAAABAAAAAA", "AAAAAABBBCBBBAAAAAA", "AAAAAAAAACAAAAAAAAA", "AAAAAAAAACAAAAAAAAA", "AAAAAAAAABAAAAAAAAA", "AAAAAAAAAAAAAAAAAAA", "AAAAAAAAAAAAAAAAAAA", "AAAAAAAAAAAAAAAAAAA")
.aisle("AAAAAAAAAAAAAAAAAAA", "AAAAAAAAAAAAAAAAAAA", "AAAAAAAAAAAAAAAAAAA", "AAAAAAAAAAAAAAAAAAA", "AAAAAAAAABAAAAAAAAA", "AAAAAAAAABAAAAAAAAA", "AAAAAAAAACAAAAAAAAA", "AAAAAAAAACAAAAAAAAA", "AAAAAAAAACAAAAAAAAA", "AAAABBCCCCCCCBBAAAA", "AAAAAAAAACAAAAAAAAA", "AAAAAAAAACAAAAAAAAA", "AAAAAAAAACAAAAAAAAA", "AAAAAAAAABAAAAAAAAA", "AAAAAAAAABAAAAAAAAA", "AAAAAAAAAAAAAAAAAAA", "AAAAAAAAAAAAAAAAAAA", "AAAAAAAAAAAAAAAAAAA", "AAAAAAAAAAAAAAAAAAA")
.aisle("AAAAAAAAAAAAAAAAAAA", "AAAAAAAAAAAAAAAAAAA", "AAAAAAAAAAAAAAAAAAA", "AAAAAAAAAAAAAAAAAAA", "AAAAAAAAAAAAAAAAAAA", "AAAAAAAAAAAAAAAAAAA", "AAAAAAAAABAAAAAAAAA", "AAAAAAAAABAAAAAAAAA", "AAAAAAAAABAAAAAAAAA", "AAAAAABBBXBBBAAAAAA", "AAAAAAAAABAAAAAAAAA", "AAAAAAAAABAAAAAAAAA", "AAAAAAAAABAAAAAAAAA", "AAAAAAAAAAAAAAAAAAA", "AAAAAAAAAAAAAAAAAAA", "AAAAAAAAAAAAAAAAAAA", "AAAAAAAAAAAAAAAAAAA", "AAAAAAAAAAAAAAAAAAA", "AAAAAAAAAAAAAAAAAAA")
    .where("A", Predicates.any())
    .where("B", Predicates.blocks("gtceu:magikstone_casing")
            .or(Predicates.autoAbilities(definition.getRecipeTypes()))
            .or(Predicates.abilities(PartAbility.MAINTENANCE).setExactLimit(1))
            .or(Predicates.abilities(PartAbility.PARALLEL_HATCH).setMaxGlobalLimited(1)))
    .where("C", Predicates.blocks("gtceu:metallurgically_enhanced_source_casing"))
    .where("D", Predicates.blocks("gtceu:source_frame"))
    .where('X', Predicates.controller(Predicates.blocks(definition.get())))
.build())
.workableCasingModel('gtceu:block/casings/solid/magikstone_casing',
        'gtceu:block/machines/chemical_bath') 
})